Workbook

Sheet 00_Overview
A1: Automation Exercise QA - Manual Test Suite
A3: Project | B3: Automation Exercise QA | D3: KPI | E3: Value | G3: Automation scope rule: Yes = automate. Later = automate after the main automation scope. No = do not automate. Priority: P1 → first, P2 → second, P3 → last
A4: System Under Test | B4: https://www.automationexercise.com/ | D4: Total Manual Test Cases | E4: =COUNTA('01_Authentication'!$A$2:$A$200)+COUNTA('02_Products'!$A$2:$A$200)+COUNTA('03_Cart'!$A$2:$A$200)+COUNTA('04_Checkout'!$A$2:$A$200)+COUNTA('05_Support'!$A$2:$A$200)+COUNTA('06_Navigation'!$A$2:$A$200)+COUNTA('07_API'!$A$2:$A$200) -> 68
A5: Requirement Source | B5: Jira simulated portfolio backlog + Automation Exercise public test/API scenarios | D5: Automation Candidate = Yes | E5: =COUNTIF('01_Authentication'!$Q$2:$Q$200,"Yes")+COUNTIF('02_Products'!$Q$2:$Q$200,"Yes")+COUNTIF('03_Cart'!$Q$2:$Q$200,"Yes")+COUNTIF('04_Checkout'!$Q$2:$Q$200,"Yes")+COUNTIF('05_Support'!$Q$2:$Q$200,"Yes")+COUNTIF('06_Navigation'!$Q$2:$Q$200,"Yes")+COUNTIF('07_API'!$Q$2:$Q$200,"Yes") -> 37
A6: Execution Status | B6: Ready for manual execution | D6: Automation Candidate = Later | E6: =COUNTIF('01_Authentication'!$Q$2:$Q$200,"Later")+COUNTIF('02_Products'!$Q$2:$Q$200,"Later")+COUNTIF('03_Cart'!$Q$2:$Q$200,"Later")+COUNTIF('04_Checkout'!$Q$2:$Q$200,"Later")+COUNTIF('05_Support'!$Q$2:$Q$200,"Later")+COUNTIF('06_Navigation'!$Q$2:$Q$200,"Later")+COUNTIF('07_API'!$Q$2:$Q$200,"Later") -> 28
D7: Automation Candidate = No | E7: =COUNTIF('01_Authentication'!$Q$2:$Q$200,"No")+COUNTIF('02_Products'!$Q$2:$Q$200,"No")+COUNTIF('03_Cart'!$Q$2:$Q$200,"No")+COUNTIF('04_Checkout'!$Q$2:$Q$200,"No")+COUNTIF('05_Support'!$Q$2:$Q$200,"No")+COUNTIF('06_Navigation'!$Q$2:$Q$200,"No")+COUNTIF('07_API'!$Q$2:$Q$200,"No") -> 3
D8: Status = Not Run | E8: =COUNTIF('01_Authentication'!$N$2:$N$200,"Not Run")+COUNTIF('02_Products'!$N$2:$N$200,"Not Run")+COUNTIF('03_Cart'!$N$2:$N$200,"Not Run")+COUNTIF('04_Checkout'!$N$2:$N$200,"Not Run")+COUNTIF('05_Support'!$N$2:$N$200,"Not Run")+COUNTIF('06_Navigation'!$N$2:$N$200,"Not Run")+COUNTIF('07_API'!$N$2:$N$200,"Not Run") -> 0
D9: Status = Fail | E9: =COUNTIF('01_Authentication'!$N$2:$N$200,"Fail")+COUNTIF('02_Products'!$N$2:$N$200,"Fail")+COUNTIF('03_Cart'!$N$2:$N$200,"Fail")+COUNTIF('04_Checkout'!$N$2:$N$200,"Fail")+COUNTIF('05_Support'!$N$2:$N$200,"Fail")+COUNTIF('06_Navigation'!$N$2:$N$200,"Fail")+COUNTIF('07_API'!$N$2:$N$200,"Fail") -> 0
A12: Epic ID | B12: Epic | C12: Sheet | D12: Test Cases | E12: Auto Yes | F12: Auto Later | G12: Auto No | H12: Not Run | I12: Pass | J12: Fail | K12: Blocked
A13: AEQA-1 | B13: Authentication & Account Management | C13: 01_Authentication | D13: =COUNTA('01_Authentication'!$A$2:$A$200) -> 13 | E13: =COUNTIF('01_Authentication'!$Q$2:$Q$200,"Yes") -> 6 | F13: =COUNTIF('01_Authentication'!$Q$2:$Q$200,"Later") -> 7 | G13: =COUNTIF('01_Authentication'!$Q$2:$Q$200,"No") -> 0 | H13: =COUNTIF('01_Authentication'!$N$2:$N$200,"Not Run") -> 0 | I13: =COUNTIF('01_Authentication'!$N$2:$N$200,"Pass") -> 13 | J13: =COUNTIF('01_Authentication'!$N$2:$N$200,"Fail") -> 0 | K13: =COUNTIF('01_Authentication'!$N$2:$N$200,"Blocked") -> 0
A14: AEQA-2 | B14: Product Catalog & Discovery | C14: 02_Products | D14: =COUNTA('02_Products'!$A$2:$A$200) -> 14 | E14: =COUNTIF('02_Products'!$Q$2:$Q$200,"Yes") -> 5 | F14: =COUNTIF('02_Products'!$Q$2:$Q$200,"Later") -> 9 | G14: =COUNTIF('02_Products'!$Q$2:$Q$200,"No") -> 0 | H14: =COUNTIF('02_Products'!$N$2:$N$200,"Not Run") -> 0 | I14: =COUNTIF('02_Products'!$N$2:$N$200,"Pass") -> 14 | J14: =COUNTIF('02_Products'!$N$2:$N$200,"Fail") -> 0 | K14: =COUNTIF('02_Products'!$N$2:$N$200,"Blocked") -> 0
A15: AEQA-3 | B15: Shopping Cart Management | C15: 03_Cart | D15: =COUNTA('03_Cart'!$A$2:$A$200) -> 8 | E15: =COUNTIF('03_Cart'!$Q$2:$Q$200,"Yes") -> 4 | F15: =COUNTIF('03_Cart'!$Q$2:$Q$200,"Later") -> 4 | G15: =COUNTIF('03_Cart'!$Q$2:$Q$200,"No") -> 0 | H15: =COUNTIF('03_Cart'!$N$2:$N$200,"Not Run") -> 0 | I15: =COUNTIF('03_Cart'!$N$2:$N$200,"Pass") -> 8 | J15: =COUNTIF('03_Cart'!$N$2:$N$200,"Fail") -> 0 | K15: =COUNTIF('03_Cart'!$N$2:$N$200,"Blocked") -> 0
A16: AEQA-4 | B16: Checkout & Order Management | C16: 04_Checkout | D16: =COUNTA('04_Checkout'!$A$2:$A$200) -> 8 | E16: =COUNTIF('04_Checkout'!$Q$2:$Q$200,"Yes") -> 5 | F16: =COUNTIF('04_Checkout'!$Q$2:$Q$200,"Later") -> 3 | G16: =COUNTIF('04_Checkout'!$Q$2:$Q$200,"No") -> 0 | H16: =COUNTIF('04_Checkout'!$N$2:$N$200,"Not Run") -> 0 | I16: =COUNTIF('04_Checkout'!$N$2:$N$200,"Pass") -> 8 | J16: =COUNTIF('04_Checkout'!$N$2:$N$200,"Fail") -> 0 | K16: =COUNTIF('04_Checkout'!$N$2:$N$200,"Blocked") -> 0
A17: AEQA-5 | B17: Customer Engagement & Support | C17: 05_Support | D17: =COUNTA('05_Support'!$A$2:$A$200) -> 6 | E17: =COUNTIF('05_Support'!$Q$2:$Q$200,"Yes") -> 2 | F17: =COUNTIF('05_Support'!$Q$2:$Q$200,"Later") -> 4 | G17: =COUNTIF('05_Support'!$Q$2:$Q$200,"No") -> 0 | H17: =COUNTIF('05_Support'!$N$2:$N$200,"Not Run") -> 0 | I17: =COUNTIF('05_Support'!$N$2:$N$200,"Pass") -> 6 | J17: =COUNTIF('05_Support'!$N$2:$N$200,"Fail") -> 0 | K17: =COUNTIF('05_Support'!$N$2:$N$200,"Blocked") -> 0
A18: AEQA-6 | B18: Navigation & UI Behavior | C18: 06_Navigation | D18: =COUNTA('06_Navigation'!$A$2:$A$200) -> 5 | E18: =COUNTIF('06_Navigation'!$Q$2:$Q$200,"Yes") -> 1 | F18: =COUNTIF('06_Navigation'!$Q$2:$Q$200,"Later") -> 1 | G18: =COUNTIF('06_Navigation'!$Q$2:$Q$200,"No") -> 3 | H18: =COUNTIF('06_Navigation'!$N$2:$N$200,"Not Run") -> 0 | I18: =COUNTIF('06_Navigation'!$N$2:$N$200,"Pass") -> 5 | J18: =COUNTIF('06_Navigation'!$N$2:$N$200,"Fail") -> 0 | K18: =COUNTIF('06_Navigation'!$N$2:$N$200,"Blocked") -> 0
A19: AEQA-7 | B19: API Testing | C19: 07_API | D19: =COUNTA('07_API'!$A$2:$A$200) -> 14 | E19: =COUNTIF('07_API'!$Q$2:$Q$200,"Yes") -> 14 | F19: =COUNTIF('07_API'!$Q$2:$Q$200,"Later") -> 0 | G19: =COUNTIF('07_API'!$Q$2:$Q$200,"No") -> 0 | H19: =COUNTIF('07_API'!$N$2:$N$200,"Not Run") -> 0 | I19: =COUNTIF('07_API'!$N$2:$N$200,"Pass") -> 14 | J19: =COUNTIF('07_API'!$N$2:$N$200,"Fail") -> 0 | K19: =COUNTIF('07_API'!$N$2:$N$200,"Blocked") -> 0
A22: How to use this workbook
A23: 1 | B23: Review the test case before execution.
A24: 2 | B24: Prepare the required test data from 99_Test_Data.
A25: 3 | B25: Execute manually on Automation Exercise.
A26: 4 | B26: Fill Actual Result, Status, and Evidence / Notes.
A27: 5 | B27: If Status = Fail, review the related AC/source first. For AC Ref = Derived, confirm expected behavior before logging a Jira Bug.
A28: 6 | B28: Retest when applicable and update Status.
A29: 7 | B29: After manual execution, automate P1 first, then P2, then P3. Rows marked No remain manual-only.

Sheet 01_Authentication
A1: Test Case ID | B1: Epic ID | C1: Epic | D1: Story ID | E1: Story | F1: AC Ref | G1: Scenario | H1: Test Case Title | I1: Precondition | J1: Test Steps | K1: Test Data | L1: Expected Result | M1: Actual Result | N1: Status | O1: Priority | P1: Test Type | Q1: Automation Candidate | R1: Auto Priority | S1: Bug ID | T1: Evidence / Notes | U1: Source Case | V1: Source URL
A2: TC-AUTH-001 | B2: AEQA-1 | C2: Authentication & Account Management | D2: AEQA-8 | E2: User Registration | F2: AC1, AC2 | G2: Register with valid information | H2: Verify a new user can register successfully | I2: User is logged out. Email address has not been registered before. | J2: 1. Open Automation Exercise. 2. Verify Home page is visible. 3. Click 'Signup / Login'. 4. Verify 'New User Signup!' is visible. 5. Enter valid name and unique email. 6. Click 'Signup'. 7. Verify 'ENTER ACCOUNT INFORMATION' is visible. 8. Fill required account information. 9. Fill required address information. 10. Click 'Create Account'. 11. Verify 'ACCOUNT CREATED!'. 12. Click 'Continue'. 13. Verify 'Logged in as <username>'. | K2: Use TD-REGISTER. Use a fresh TD-REGISTER Email (test001/test002/test003...). | L2: Account is created successfully. 'ACCOUNT CREATED!' is displayed. After Continue, user is logged in and 'Logged in as <username>' is displayed. | N2: Pass | O2: High | P2: Positive / Functional | Q2: Yes | R2: P1 | U2: UI Test Case 1 | V2: https://www.automationexercise.com/test_cases
A3: TC-AUTH-002 | B3: AEQA-1 | C3: Authentication & Account Management | D3: AEQA-8 | E3: User Registration | F3: AC3 | G3: Register with existing email | H3: Verify registration is rejected for an existing email | I3: A registered account already exists. User is logged out. | J3: 1. Open Automation Exercise. 2. Click 'Signup / Login'. 3. Verify 'New User Signup!' is visible. 4. Enter a name. 5. Enter an already registered email. 6. Click 'Signup'. | K3: Use TD-EXISTING. | L3: Registration does not continue. 'Email Address already exist!' is displayed. | N3: Pass | O3: High | P3: Negative / Functional | Q3: Yes | R3: P2 | U3: UI Test Case 5 | V3: https://www.automationexercise.com/test_cases
A4: TC-AUTH-003 | B4: AEQA-1 | C4: Authentication & Account Management | D4: AEQA-8 | E4: User Registration | F4: Derived | G4: Validate required signup fields | H4: Verify signup cannot continue when Name is empty | I4: User is on the Signup / Login page. | J4: 1. Leave Name empty. 2. Enter a valid new email. 3. Click 'Signup'. | K4: Use TD-REGISTER, but leave Name blank. Use a fresh Email. | L4: Signup does not continue and required-field validation prevents submission. | N4: Pass | O4: Medium | P4: Negative / Validation | Q4: Later | R4: P3 | U4: Exploratory validation derived from form constraints | V4: https://www.automationexercise.com/test_cases
A5: TC-AUTH-004 | B5: AEQA-1 | C5: Authentication & Account Management | D5: AEQA-8 | E5: User Registration | F5: Derived | G5: Validate required signup fields | H5: Verify signup cannot continue when Email is empty | I5: User is on the Signup / Login page. | J5: 1. Enter a valid name. 2. Leave Email empty. 3. Click 'Signup'. | K5: Use TD-REGISTER Name; leave Email blank. | L5: Signup does not continue and required-field validation prevents submission. | N5: Pass | O5: Medium | P5: Negative / Validation | Q5: Later | R5: P3 | U5: Exploratory validation derived from form constraints | V5: https://www.automationexercise.com/test_cases
A6: TC-AUTH-005 | B6: AEQA-1 | C6: Authentication & Account Management | D6: AEQA-8 | E6: User Registration | F6: Derived | G6: Validate email format | H6: Verify signup rejects an invalid email format | I6: User is on the Signup / Login page. | J6: 1. Enter a valid name. 2. Enter an invalid email format such as 'testemail'. 3. Click 'Signup'. | K6: Use TD-REGISTER Name + TD-NEGATIVE Invalid Email Format. | L6: Signup does not continue with an invalid email format. | N6: Pass | O6: Medium | P6: Negative / Validation | Q6: Later | R6: P3 | U6: Exploratory validation derived from form constraints | V6: https://www.automationexercise.com/test_cases
A7: TC-AUTH-006 | B7: AEQA-1 | C7: Authentication & Account Management | D7: AEQA-9 | E7: User Login | F7: AC1 | G7: Login with valid credentials | H7: Verify registered user can login with valid credentials | I7: A registered account exists. User is logged out. | J7: 1. Open Automation Exercise. 2. Click 'Signup / Login'. 3. Verify 'Login to your account' is visible. 4. Enter registered email and correct password. 5. Click 'Login'. | K7: Use TD-EXISTING. | L7: Login succeeds and 'Logged in as <username>' is displayed. | N7: Pass | O7: High | P7: Positive / Functional | Q7: Yes | R7: P1 | U7: UI Test Case 2 | V7: https://www.automationexercise.com/test_cases
A8: TC-AUTH-007 | B8: AEQA-1 | C8: Authentication & Account Management | D8: AEQA-9 | E8: User Login | F8: AC2 | G8: Login with invalid credentials | H8: Verify login fails with invalid email and valid password | I8: User is logged out. | J8: 1. Open Signup / Login page. 2. Enter an unregistered email. 3. Enter a valid-format password. 4. Click 'Login'. | K8: Use TD-NEGATIVE Unregistered Email + TD-EXISTING Password. | L8: User is not logged in and 'Your email or password is incorrect!' is displayed. | N8: Pass | O8: High | P8: Negative / Functional | Q8: Yes | R8: P2 | U8: UI Test Case 3 | V8: https://www.automationexercise.com/test_cases
A9: TC-AUTH-008 | B9: AEQA-1 | C9: Authentication & Account Management | D9: AEQA-9 | E9: User Login | F9: AC2 | G9: Login with invalid credentials | H9: Verify login fails with valid email and invalid password | I9: A registered account exists. User is logged out. | J9: 1. Open Signup / Login page. 2. Enter registered email. 3. Enter incorrect password. 4. Click 'Login'. | K9: Use TD-EXISTING Email + TD-NEGATIVE Wrong Password. | L9: User is not logged in and 'Your email or password is incorrect!' is displayed. | N9: Pass | O9: High | P9: Negative / Functional | Q9: Later | R9: P3 | U9: UI Test Case 3 | V9: https://www.automationexercise.com/test_cases
A10: TC-AUTH-009 | B10: AEQA-1 | C10: Authentication & Account Management | D10: AEQA-9 | E10: User Login | F10: Derived | G10: Validate required login fields | H10: Verify login cannot continue when Email is empty | I10: User is on the Signup / Login page. | J10: 1. Leave Email empty. 2. Enter a password. 3. Click 'Login'. | K10: Leave Email blank + use TD-EXISTING Password. | L10: Login does not continue and required-field validation prevents submission. | N10: Pass | O10: Medium | P10: Negative / Validation | Q10: Later | R10: P3 | U10: Exploratory validation derived from form constraints | V10: https://www.automationexercise.com/test_cases
A11: TC-AUTH-010 | B11: AEQA-1 | C11: Authentication & Account Management | D11: AEQA-9 | E11: User Login | F11: Derived | G11: Validate required login fields | H11: Verify login cannot continue when Password is empty | I11: User is on the Signup / Login page. | J11: 1. Enter a registered email. 2. Leave Password empty. 3. Click 'Login'. | K11: Use TD-EXISTING Email + leave Password blank. | L11: Login does not continue and required-field validation prevents submission. | N11: Pass | O11: Medium | P11: Negative / Validation | Q11: Later | R11: P3 | U11: Exploratory validation derived from form constraints | V11: https://www.automationexercise.com/test_cases
A12: TC-AUTH-011 | B12: AEQA-1 | C12: Authentication & Account Management | D12: AEQA-10 | E12: User Logout | F12: AC1 | G12: Logout authenticated user | H12: Verify a logged-in user can logout successfully | I12: User is logged in. | J12: 1. Verify 'Logged in as <username>' is visible. 2. Click 'Logout'. | K12: Use TD-EXISTING. | L12: User is logged out, redirected to Signup / Login page, and authenticated user state is no longer shown. | N12: Pass | O12: High | P12: Positive / Functional | Q12: Yes | R12: P1 | U12: UI Test Case 4 | V12: https://www.automationexercise.com/test_cases
A13: TC-AUTH-012 | B13: AEQA-1 | C13: Authentication & Account Management | D13: AEQA-11 | E13: Account Deletion | F13: AC1 | G13: Delete authenticated account | H13: Verify a logged-in user can delete the account | I13: User is logged in with a disposable test account. | J13: 1. Verify user is logged in. 2. Click 'Delete Account'. 3. Verify deletion confirmation. | K13: Use TD-REGISTER with the next fresh email. Keep these credentials for TC-AUTH-013. | L13: Account is deleted successfully and 'ACCOUNT DELETED!' is displayed. | N13: Pass | O13: High | P13: Positive / Functional | Q13: Yes | R13: P1 | U13: UI Test Case 1 / account cleanup step | V13: https://www.automationexercise.com/test_cases
A14: TC-AUTH-013 | B14: AEQA-1 | C14: Authentication & Account Management | D14: AEQA-11 | E14: Account Deletion | F14: Derived | G14: Verify account lifecycle after deletion | H14: Verify deleted account cannot login again | I14: A disposable account was deleted successfully. | J14: 1. Open Signup / Login page. 2. Enter the deleted account email and password. 3. Click 'Login'. | K14: Use the disposable credentials created and deleted in TC-AUTH-012. | L14: User is not logged in and the invalid-credentials error is displayed. | N14: Pass | O14: High | P14: Negative / Regression | Q14: Later | R14: P3 | U14: Derived lifecycle regression | V14: https://www.automationexercise.com/test_cases

Sheet 02_Products
A1: Test Case ID | B1: Epic ID | C1: Epic | D1: Story ID | E1: Story | F1: AC Ref | G1: Scenario | H1: Test Case Title | I1: Precondition | J1: Test Steps | K1: Test Data | L1: Expected Result | M1: Actual Result | N1: Status | O1: Priority | P1: Test Type | Q1: Automation Candidate | R1: Auto Priority | S1: Bug ID | T1: Evidence / Notes | U1: Source Case | V1: Source URL
A2: TC-PROD-001 | B2: AEQA-2 | C2: Product Catalog & Discovery | D2: AEQA-12 | E2: View Product Catalog | F2: AC1 | G2: View product catalog | H2: Verify user can open the Products page | I2: User is on the Home page. | J2: 1. Click 'Products'. 2. Observe the destination page. | K2: N/A | L2: User is navigated to the ALL PRODUCTS page successfully. | N2: Pass | O2: High | P2: Positive / Functional | Q2: Later | R2: P3 | U2: UI Test Case 8 | V2: https://www.automationexercise.com/test_cases
A3: TC-PROD-002 | B3: AEQA-2 | C3: Product Catalog & Discovery | D3: AEQA-12 | E3: View Product Catalog | F3: AC1 | G3: View product catalog | H3: Verify available products are visible on the Products page | I3: User is on the ALL PRODUCTS page. | J3: 1. Observe the product list. | K3: N/A | L3: The products list is visible and contains available products. | N3: Pass | O3: High | P3: Positive / UI | Q3: Later | R3: P3 | U3: UI Test Case 8 | V3: https://www.automationexercise.com/test_cases
A4: TC-PROD-003 | B4: AEQA-2 | C4: Product Catalog & Discovery | D4: AEQA-13 | E4: View Product Details | F4: AC1 | G4: View product details | H4: Verify user can open the first product detail page | I4: User is on the ALL PRODUCTS page. | J4: 1. Click 'View Product' for the first product. | K4: First visible product | L4: User lands on the Product Detail page. | N4: Pass | O4: High | P4: Positive / Functional | Q4: Later | R4: P3 | U4: UI Test Case 8 | V4: https://www.automationexercise.com/test_cases
A5: TC-PROD-004 | B5: AEQA-2 | C5: Product Catalog & Discovery | D5: AEQA-13 | E5: View Product Details | F5: AC1 | G5: View product details | H5: Verify core product information is displayed | I5: User is on a Product Detail page. | J5: 1. Verify product name. 2. Verify category. 3. Verify price. 4. Verify availability. 5. Verify condition. 6. Verify brand. | K5: Any available product | L5: Name, category, price, availability, condition, and brand are all visible. | N5: Pass | O5: High | P5: Positive / UI | Q5: Yes | R5: P1 | U5: UI Test Case 8 | V5: https://www.automationexercise.com/test_cases
A6: TC-PROD-005 | B6: AEQA-2 | C6: Product Catalog & Discovery | D6: AEQA-14 | E6: Search Products | F6: AC1 | G6: Search with product keyword | H6: Verify search returns products related to 'top' | I6: User is on the ALL PRODUCTS page. | J6: 1. Enter 'top' in the search input. 2. Click Search. 3. Verify 'SEARCHED PRODUCTS'. 4. Review returned products. | K6: Use TD-SEARCH Keyword 1. | L6: 'SEARCHED PRODUCTS' is visible and returned products are related to the search keyword. | N6: Pass | O6: High | P6: Positive / Functional | Q6: Yes | R6: P1 | U6: UI Test Case 9 | V6: https://www.automationexercise.com/test_cases
A7: TC-PROD-006 | B7: AEQA-2 | C7: Product Catalog & Discovery | D7: AEQA-14 | E7: Search Products | F7: AC1 | G7: Search with product keyword | H7: Verify search works with another supported keyword | I7: User is on the ALL PRODUCTS page. | J7: 1. Enter 'jean' in the search input. 2. Click Search. 3. Verify searched products. | K7: Use TD-SEARCH Keyword 2. | L7: Searched products section is displayed and matching products are shown. | N7: Pass | O7: Medium | P7: Positive / Data-driven | Q7: Later | R7: P3 | U7: UI Test Case 9 | V7: https://www.automationexercise.com/test_cases
A8: TC-PROD-007 | B8: AEQA-2 | C8: Product Catalog & Discovery | D8: AEQA-15 | E8: Browse Products by Category | F8: AC1 | G8: Browse a product category | H8: Verify products can be viewed by Women category and subcategory | I8: Categories are visible on the left sidebar. | J8: 1. Click 'Women'. 2. Click a Women subcategory such as 'Dress'. 3. Observe the category page and products. | K8: Category: Women Subcategory: Dress | L8: Selected category page is displayed and products for the selected category are shown. | N8: Pass | O8: High | P8: Positive / Functional | Q8: Yes | R8: P1 | U8: UI Test Case 18 | V8: https://www.automationexercise.com/test_cases
A9: TC-PROD-008 | B9: AEQA-2 | C9: Product Catalog & Discovery | D9: AEQA-15 | E9: Browse Products by Category | F9: AC2 | G9: Switch product category | H9: Verify user can switch from Women to a Men subcategory | I9: User is viewing a Women category page. | J9: 1. Select a subcategory under 'Men'. 2. Observe the destination page. | K9: Category: Men Any available subcategory | L9: User is navigated to the selected Men category page and its products are displayed. | N9: Pass | O9: Medium | P9: Positive / Functional | Q9: Later | R9: P3 | U9: UI Test Case 18 | V9: https://www.automationexercise.com/test_cases
A10: TC-PROD-009 | B10: AEQA-2 | C10: Product Catalog & Discovery | D10: AEQA-16 | E10: Browse Products by Brand | F10: AC1 | G10: Browse products by brand | H10: Verify user can view products for a selected brand | I10: User is on the Products page and Brands are visible. | J10: 1. Click any brand name. 2. Observe the brand page. | K10: Use any visible brand. | L10: User is navigated to the selected brand page and brand products are displayed. | N10: Pass | O10: High | P10: Positive / Functional | Q10: Yes | R10: P1 | U10: UI Test Case 19 | V10: https://www.automationexercise.com/test_cases
A11: TC-PROD-010 | B11: AEQA-2 | C11: Product Catalog & Discovery | D11: AEQA-16 | E11: Browse Products by Brand | F11: AC2 | G11: Switch brand | H11: Verify user can switch from one brand to another | I11: User is viewing products for one brand. | J11: 1. Click another brand link. 2. Observe the destination page. | K11: Use a second visible brand. | L11: User is navigated to the newly selected brand page and corresponding products are displayed. | N11: Pass | O11: Medium | P11: Positive / Functional | Q11: Later | R11: P3 | U11: UI Test Case 19 | V11: https://www.automationexercise.com/test_cases
A12: TC-PROD-011 | B12: AEQA-2 | C12: Product Catalog & Discovery | D12: AEQA-17 | E12: Submit Product Review | F12: AC1 | G12: Submit product review | H12: Verify a valid product review can be submitted | I12: User is on a Product Detail page and 'Write Your Review' is visible. | J12: 1. Enter name. 2. Enter email. 3. Enter review text. 4. Click 'Submit'. | K12: Use TD-REVIEW. | L12: Review is submitted and 'Thank you for your review.' is displayed. | N12: Pass | O12: Medium | P12: Positive / Functional | Q12: Later | R12: P3 | U12: UI Test Case 21 | V12: https://www.automationexercise.com/test_cases
A13: TC-PROD-012 | B13: AEQA-2 | C13: Product Catalog & Discovery | D13: AEQA-17 | E13: Submit Product Review | F13: Derived | G13: Validate review form | H13: Verify review is not submitted when required email is empty | I13: User is on a Product Detail page. | J13: 1. Enter name. 2. Leave email empty. 3. Enter review text. 4. Click 'Submit'. | K13: Use TD-REVIEW, but leave Email blank. | L13: Submission should be prevented by required-field validation. | N13: Pass | O13: Low | P13: Negative / Validation | Q13: Later | R13: P3 | U13: Exploratory validation derived from form constraints | V13: https://www.automationexercise.com/test_cases
... A15: TC-PROD-014 | B15: AEQA-2 | C15: Product Catalog & Discovery | D15: AEQA-18 | E15: View Recommended Products | F15: AC2 | G15: Add recommended product to cart | H15: Verify a recommended product can be added to cart | I15: Recommended Items section is visible. | J15: 1. Click 'Add To Cart' on a recommended product. 2. Click 'View Cart'. | K15: Any recommended product | L15: Selected recommended product is displayed in the Cart. | N15: Pass | O15: High | P15: Positive / Functional | Q15: Yes | R15: P1 | U15: UI Test Case 22 | V15: https://www.automationexercise.com/test_cases

Sheet 03_Cart
A1: Test Case ID | B1: Epic ID | C1: Epic | D1: Story ID | E1: Story | F1: AC Ref | G1: Scenario | H1: Test Case Title | I1: Precondition | J1: Test Steps | K1: Test Data | L1: Expected Result | M1: Actual Result | N1: Status | O1: Priority | P1: Test Type | Q1: Automation Candidate | R1: Auto Priority | S1: Bug ID | T1: Evidence / Notes | U1: Source Case | V1: Source URL
A2: TC-CART-001 | B2: AEQA-3 | C2: Shopping Cart Management | D2: AEQA-19 | E2: Add Products to Cart | F2: AC1 | G2: Add one product to cart | H2: Verify one product can be added to cart | I2: User is viewing an available product. | J2: 1. Click 'Add to cart'. 2. Click 'View Cart'. | K2: Any available product | L2: Selected product is displayed in the Cart. | N2: Pass | O2: High | P2: Positive / Functional | Q2: Later | R2: P3 | U2: Derived from UI Test Case 12 | V2: https://www.automationexercise.com/test_cases
A3: TC-CART-002 | B3: AEQA-3 | C3: Shopping Cart Management | D3: AEQA-19 | E3: Add Products to Cart | F3: AC2 | G3: Add multiple products to cart | H3: Verify two products are added with correct cart details | I3: User is on the Products page. | J3: 1. Add first product to cart. 2. Click 'Continue Shopping'. 3. Add second product. 4. Click 'View Cart'. 5. Verify both products. 6. Verify price, quantity, and total. | K3: First two available products | L3: Both products are present and their price, quantity, and total values are displayed correctly. | N3: Pass | O3: High | P3: Positive / Functional | Q3: Yes | R3: P1 | U3: UI Test Case 12 | V3: https://www.automationexercise.com/test_cases
A4: TC-CART-003 | B4: AEQA-3 | C4: Shopping Cart Management | D4: AEQA-19 | E4: Add Products to Cart | F4: AC2 | G4: Continue shopping after adding product | H4: Verify Continue Shopping keeps previously added item | I4: One product has just been added to cart. | J4: 1. Click 'Continue Shopping'. 2. Add a second product. 3. Open Cart. | K4: Two available products | L4: Previously added product remains in the Cart together with the second product. | N4: Pass | O4: Medium | P4: Positive / Regression | Q4: Later | R4: P3 | U4: UI Test Case 12 | V4: https://www.automationexercise.com/test_cases
A5: TC-CART-004 | B5: AEQA-3 | C5: Shopping Cart Management | D5: AEQA-20 | E5: Update Product Quantity | F5: AC1 | G5: Add product with selected quantity | H5: Verify selected quantity 4 is preserved in cart | I5: User is on a Product Detail page. | J5: 1. Set quantity to 4. 2. Click 'Add to cart'. 3. Click 'View Cart'. | K5: Quantity: 4 | L5: Product is displayed in Cart with quantity exactly 4. | N5: Pass | O5: High | P5: Positive / Functional | Q5: Yes | R5: P1 | U5: UI Test Case 13 | V5: https://www.automationexercise.com/test_cases
A6: TC-CART-005 | B6: AEQA-3 | C6: Shopping Cart Management | D6: AEQA-20 | E6: Update Product Quantity | F6: AC1 | G6: Verify default quantity | H6: Verify default quantity is carried to cart | I6: User is on a Product Detail page. | J6: 1. Leave quantity at its default value. 2. Add product to cart. 3. Open Cart. | K6: Default quantity | L6: Cart displays the same default quantity selected on Product Detail page. | N6: Pass | O6: Medium | P6: Positive / Functional | Q6: Later | R6: P3 | U6: Derived from Story/AC | V6: https://www.automationexercise.com/test_cases
A7: TC-CART-006 | B7: AEQA-3 | C7: Shopping Cart Management | D7: AEQA-21 | E7: Remove Product from Cart | F7: AC1 | G7: Remove product from cart | H7: Verify a product can be removed from the cart | I7: Cart contains at least one product. | J7: 1. Open Cart. 2. Click the 'X' remove control for a product. | K7: Any cart product | L7: Selected product is removed and is no longer displayed in the Cart. | N7: Pass | O7: High | P7: Positive / Functional | Q7: Yes | R7: P1 | U7: UI Test Case 17 | V7: https://www.automationexercise.com/test_cases
A8: TC-CART-007 | B8: AEQA-3 | C8: Shopping Cart Management | D8: AEQA-21 | E8: Remove Product from Cart | F8: AC1 | G8: Remove one of multiple cart products | H8: Verify removing one item does not remove other items | I8: Cart contains at least two products. | J8: 1. Remove one product using its 'X' control. 2. Observe remaining cart contents. | K8: Two or more cart products | L8: Selected product is removed and the other product(s) remain in the Cart. | N8: Pass | O8: Medium | P8: Positive / Regression | Q8: Later | R8: P3 | U8: Derived from UI Test Case 17 | V8: https://www.automationexercise.com/test_cases
A9: TC-CART-008 | B9: AEQA-3 | C9: Shopping Cart Management | D9: AEQA-22 | E9: Preserve Cart After Login | F9: AC1 | G9: Preserve cart after login | H9: Verify cart products remain after user logs in | I9: User is logged out. A registered account exists. | J9: 1. Search for a product. 2. Add searched product(s) to cart. 3. Open Cart and verify items. 4. Click 'Signup / Login'. 5. Login with valid credentials. 6. Open Cart again. | K9: Use TD-EXISTING + TD-SEARCH Keyword 1. | L9: Products added before login remain visible in the Cart after successful login. | N9: Pass | O9: High | P9: Positive / Regression | Q9: Yes | R9: P1 | U9: UI Test Case 20 | V9: https://www.automationexercise.com/test_cases

Sheet 04_Checkout
A1: Test Case ID | B1: Epic ID | C1: Epic | D1: Story ID | E1: Story | F1: AC Ref | G1: Scenario | H1: Test Case Title | I1: Precondition | J1: Test Steps | K1: Test Data | L1: Expected Result | M1: Actual Result | N1: Status | O1: Priority | P1: Test Type | Q1: Automation Candidate | R1: Auto Priority | S1: Bug ID | T1: Evidence / Notes | U1: Source Case | V1: Source URL
A2: TC-CHK-001 | B2: AEQA-4 | C2: Checkout & Order Management | D2: AEQA-24 | E2: Register During Checkout | F2: AC1, AC2 | G2: Register during checkout | H2: Verify guest user can register during checkout and continue | I2: User is logged out and Cart contains at least one product. | J2: 1. Open Cart. 2. Click 'Proceed To Checkout'. 3. Click 'Register / Login'. 4. Complete signup with valid unique data. 5. Verify 'ACCOUNT CREATED!'. 6. Click 'Continue'. 7. Return to Cart. 8. Click 'Proceed To Checkout'. | K2: Use TD-REGISTER with a fresh email + any available product. | L2: Registration succeeds and the user can return to the checkout flow; Address Details and Review Your Order are displayed. | N2: Pass | O2: High | P2: Positive / E2E | Q2: Yes | R2: P1 | U2: UI Test Case 14 | V2: https://www.automationexercise.com/test_cases
A3: TC-CHK-002 | B3: AEQA-4 | C3: Checkout & Order Management | D3: AEQA-25 | E3: Checkout as Existing User | F3: AC1 | G3: Checkout as logged-in user | H3: Verify existing user can proceed from cart to checkout | I3: Registered user exists and is logged in. Cart contains at least one product. | J3: 1. Open Cart. 2. Verify cart page. 3. Click 'Proceed To Checkout'. | K3: Use TD-EXISTING. | L3: Checkout page is displayed with Address Details and Review Your Order. | N3: Pass | O3: High | P3: Positive / E2E | Q3: Yes | R3: P1 | U3: UI Test Case 16 | V3: https://www.automationexercise.com/test_cases
A4: TC-CHK-003 | B4: AEQA-4 | C4: Checkout & Order Management | D4: AEQA-26 | E4: Verify Checkout Addresses | F4: AC1 | G4: Verify delivery address | H4: Verify delivery address matches registration data | I4: User registered with known address data, is logged in, and has proceeded to checkout. | J4: 1. Compare Delivery Address with registration address. | K4: Use the TD-REGISTER address values used to create the account for this checkout flow. | L4: Delivery Address matches the address entered during registration. | N4: Pass | O4: High | P4: Positive / Data Integrity | Q4: Yes | R4: P1 | U4: UI Test Case 23 | V4: https://www.automationexercise.com/test_cases
A5: TC-CHK-004 | B5: AEQA-4 | C5: Checkout & Order Management | D5: AEQA-26 | E5: Verify Checkout Addresses | F5: AC2 | G5: Verify billing address | H5: Verify billing address matches registration data | I5: User registered with known address data, is logged in, and has proceeded to checkout. | J5: 1. Compare Billing Address with registration address. | K5: Use the TD-REGISTER address values used to create the account for this checkout flow. | L5: Billing Address matches the address entered during registration. | N5: Pass | O5: High | P5: Positive / Data Integrity | Q5: Later | R5: P3 | U5: UI Test Case 23 | V5: https://www.automationexercise.com/test_cases
A6: TC-CHK-005 | B6: AEQA-4 | C6: Checkout & Order Management | D6: AEQA-27 | E6: Place Order and Payment | F6: AC1, AC2 | G6: Place order with valid payment | H6: Verify user can complete order with valid payment data | I6: User is logged in, Cart contains product(s), and Checkout page is displayed. | J6: 1. Enter order comment. 2. Click 'Place Order'. 3. Enter Name on Card, Card Number, CVC, Expiration. 4. Click 'Pay and Confirm Order'. | K6: Use TD-ORDER Comment + TD-PAYMENT. | L6: Payment is accepted and order success confirmation is displayed. | N6: Pass | O6: High | P6: Positive / E2E | Q6: Yes | R6: P1 | U6: UI Test Case 16 | V6: https://www.automationexercise.com/test_cases
A7: TC-CHK-006 | B7: AEQA-4 | C7: Checkout & Order Management | D7: AEQA-27 | E7: Place Order and Payment | F7: Derived | G7: Validate payment form | H7: Verify payment cannot be submitted when Card Number is empty | I7: User is on the Payment page. | J7: 1. Enter all payment fields except Card Number. 2. Click 'Pay and Confirm Order'. | K7: Use TD-PAYMENT, but leave Card Number blank. | L7: Order should not be completed and required-field validation should prevent payment submission. | N7: Pass | O7: Medium | P7: Negative / Validation | Q7: Later | R7: P3 | U7: Exploratory validation derived from form constraints | V7: https://www.automationexercise.com/test_cases
A8: TC-CHK-007 | B8: AEQA-4 | C8: Checkout & Order Management | D8: AEQA-28 | E8: Download Invoice | F8: AC1 | G8: Download invoice | H8: Verify invoice can be downloaded after successful order | I8: A purchase order was completed successfully. | J8: 1. Click 'Download Invoice'. 2. Confirm a file download is triggered. | K8: Successful order from TC-CHK-005. | L8: Invoice file downloads successfully. | N8: Pass | O8: High | P8: Positive / Download | Q8: Yes | R8: P1 | U8: UI Test Case 24 | V8: https://www.automationexercise.com/test_cases
A9: TC-CHK-008 | B9: AEQA-4 | C9: Checkout & Order Management | D9: AEQA-28 | E9: Download Invoice | F9: AC2 | G9: Continue after invoice download | H9: Verify user can continue after downloading invoice | I9: Invoice was downloaded successfully. | J9: 1. Click 'Continue'. | K9: N/A | L9: User can continue using the website after invoice download. | N9: Pass | O9: Medium | P9: Positive / Navigation | Q9: Later | R9: P3 | U9: UI Test Case 24 | V9: https://www.automationexercise.com/test_cases

Sheet 05_Support
A1: Test Case ID | B1: Epic ID | C1: Epic | D1: Story ID | E1: Story | F1: AC Ref | G1: Scenario | H1: Test Case Title | I1: Precondition | J1: Test Steps | K1: Test Data | L1: Expected Result | M1: Actual Result | N1: Status | O1: Priority | P1: Test Type | Q1: Automation Candidate | R1: Auto Priority | S1: Bug ID | T1: Evidence / Notes | U1: Source Case | V1: Source URL
A2: TC-SUP-001 | B2: AEQA-5 | C2: Customer Engagement & Support | D2: AEQA-29 | E2: Contact Us | F2: AC1 | G2: Submit contact request with attachment | H2: Verify Contact Us form can be submitted with a file | I2: User is on the Home page. | J2: 1. Click 'Contact Us'. 2. Verify 'GET IN TOUCH'. 3. Enter name, email, subject, message. 4. Upload a test file. 5. Click 'Submit'. 6. Confirm browser dialog if shown. | K2: Use TD-CONTACT + TD-FILE. | L2: 'Success! Your details have been submitted successfully.' is displayed. | N2: Pass | O2: Medium | P2: Positive / Functional | Q2: Yes | R2: P1 | U2: UI Test Case 6 | V2: https://www.automationexercise.com/test_cases
A3: TC-SUP-002 | B3: AEQA-5 | C3: Customer Engagement & Support | D3: AEQA-29 | E3: Contact Us | F3: AC1 | G3: Submit contact request without attachment | H3: Verify Contact Us form can be submitted without optional attachment | I3: User is on the Contact Us page. | J3: 1. Enter valid name, email, subject, message. 2. Do not attach a file. 3. Click 'Submit'. 4. Confirm browser dialog if shown. | K3: Use TD-CONTACT. | L3: Contact request is submitted successfully and success confirmation is displayed. | N3: Pass | O3: Low | P3: Positive / Functional | Q3: Later | R3: P3 | U3: Derived from AC: attachment is optional | V3: https://www.automationexercise.com/test_cases
A4: TC-SUP-003 | B4: AEQA-5 | C4: Customer Engagement & Support | D4: AEQA-29 | E4: Contact Us | F4: Derived | G4: Validate contact form | H4: Verify contact request is not submitted when Email is empty | I4: User is on the Contact Us page. | J4: 1. Enter name, subject, message. 2. Leave Email empty. 3. Click 'Submit'. | K4: Use TD-CONTACT, but leave Email blank. | L4: Submission should be prevented by required-field validation. | N4: Pass | O4: Low | P4: Negative / Validation | Q4: Later | R4: P3 | U4: Exploratory validation derived from form constraints | V4: https://www.automationexercise.com/test_cases
A5: TC-SUB-001 | B5: AEQA-5 | C5: Customer Engagement & Support | D5: AEQA-30 | E5: Email Subscription | F5: AC1 | G5: Subscribe from Home page | H5: Verify email subscription works from Home page | I5: User is on the Home page. | J5: 1. Scroll to footer. 2. Verify 'SUBSCRIPTION'. 3. Enter valid email. 4. Click arrow button. | K5: Use TD-SUBSCRIPTION Home Email. | L5: 'You have been successfully subscribed!' is displayed. | N5: Pass | O5: Medium | P5: Positive / Functional | Q5: Yes | R5: P1 | U5: UI Test Case 10 | V5: https://www.automationexercise.com/test_cases
A6: TC-SUB-002 | B6: AEQA-5 | C6: Customer Engagement & Support | D6: AEQA-30 | E6: Email Subscription | F6: AC2 | G6: Subscribe from Cart page | H6: Verify email subscription works from Cart page | I6: User is on the Cart page. | J6: 1. Scroll to footer. 2. Verify 'SUBSCRIPTION'. 3. Enter valid email. 4. Click arrow button. | K6: Use TD-SUBSCRIPTION Cart Email. | L6: 'You have been successfully subscribed!' is displayed. | N6: Pass | O6: Medium | P6: Positive / Functional | Q6: Later | R6: P3 | U6: UI Test Case 11 | V6: https://www.automationexercise.com/test_cases
A7: TC-SUB-003 | B7: AEQA-5 | C7: Customer Engagement & Support | D7: AEQA-30 | E7: Email Subscription | F7: Derived | G7: Validate subscription email | H7: Verify subscription does not accept empty email | I7: Subscription section is visible. | J7: 1. Leave subscription email empty. 2. Click arrow button. | K7: Leave subscription Email blank. | L7: Subscription should not complete and required-field validation should prevent submission. | N7: Pass | O7: Low | P7: Negative / Validation | Q7: Later | R7: P3 | U7: Exploratory validation derived from form constraints | V7: https://www.automationexercise.com/test_cases

Sheet 06_Navigation
A1: Test Case ID | B1: Epic ID | C1: Epic | D1: Story ID | E1: Story | F1: AC Ref | G1: Scenario | H1: Test Case Title | I1: Precondition | J1: Test Steps | K1: Test Data | L1: Expected Result | M1: Actual Result | N1: Status | O1: Priority | P1: Test Type | Q1: Automation Candidate | R1: Auto Priority | S1: Bug ID | T1: Evidence / Notes | U1: Source Case | V1: Source URL
A2: TC-NAV-001 | B2: AEQA-6 | C2: Navigation & UI Behavior | D2: AEQA-31 | E2: Access Test Cases Page | F2: AC1 | G2: Navigate to Test Cases page | H2: Verify Test Cases navigation opens the Test Cases page | I2: User is on the Home page. | J2: 1. Click 'Test Cases'. | K2: N/A | L2: User is navigated to the Test Cases page successfully. | N2: Pass | O2: Medium | P2: Positive / Navigation | Q2: Yes | R2: P1 | U2: UI Test Case 7 | V2: https://www.automationexercise.com/test_cases
A3: TC-NAV-002 | B3: AEQA-6 | C3: Navigation & UI Behavior | D3: AEQA-32 | E3: Scroll to Top Using Arrow | F3: AC1 | G3: Scroll to bottom using page scroll | H3: Verify footer content and scroll-to-top arrow appear near the bottom | I3: User is on the Home page. | J3: 1. Scroll to the bottom of the page. 2. Verify 'SUBSCRIPTION'. 3. Observe scroll-to-top arrow. | K3: N/A | L3: Footer area is visible and scroll-to-top arrow is available. | N3: Pass | O3: Low | P3: Positive / UI | Q3: No | U3: UI Test Case 25 | V3: https://www.automationexercise.com/test_cases
A4: TC-NAV-003 | B4: AEQA-6 | C4: Navigation & UI Behavior | D4: AEQA-32 | E4: Scroll to Top Using Arrow | F4: AC2 | G4: Return to top using arrow | H4: Verify scroll-to-top arrow moves user back to top | I4: User is near the bottom of Home page and scroll-to-top arrow is visible. | J4: 1. Click the scroll-to-top arrow. | K4: N/A | L4: Page scrolls to the top and 'Full-Fledged practice website for Automation Engineers' is visible. | N4: Pass | O4: Low | P4: Positive / UI | Q4: Later | R4: P3 | U4: UI Test Case 25 | V4: https://www.automationexercise.com/test_cases
A5: TC-NAV-004 | B5: AEQA-6 | C5: Navigation & UI Behavior | D5: AEQA-33 | E5: Manual Page Scrolling | F5: AC1 | G5: Manual scroll to bottom | H5: Verify user can manually scroll to the footer | I5: User is at the top of the Home page. | J5: 1. Manually scroll down to the bottom. | K5: N/A | L5: Footer area is reachable and 'SUBSCRIPTION' is visible. | N5: Pass | O5: Low | P5: Positive / UI | Q5: No | U5: UI Test Case 26 | V5: https://www.automationexercise.com/test_cases
A6: TC-NAV-005 | B6: AEQA-6 | C6: Navigation & UI Behavior | D6: AEQA-33 | E6: Manual Page Scrolling | F6: AC2 | G6: Manual scroll back to top | H6: Verify user can manually return to the top | I6: User is near the bottom of the Home page. | J6: 1. Manually scroll upward to the top. | K6: N/A | L6: Top-page content is visible again, including 'Full-Fledged practice website for Automation Engineers'. | N6: Pass | O6: Low | P6: Positive / UI | Q6: No | U6: UI Test Case 26 | V6: https://www.automationexercise.com/test_cases

Sheet 07_API
A1: Test Case ID | B1: Epic ID | C1: Epic | D1: Story ID | E1: Story | F1: AC Ref | G1: Scenario | H1: Test Case Title | I1: Precondition | J1: Test Steps | K1: Test Data | L1: Expected Result | M1: Actual Result | N1: Status | O1: Priority | P1: Test Type | Q1: Automation Candidate | R1: Auto Priority | S1: Bug ID | T1: Evidence / Notes | U1: Source Case | V1: Source URL
A2: TC-API-001 | B2: AEQA-7 | C2: API Testing | D2: AEQA-34 | E2: Product APIs | F2: AC1 | G2: Retrieve product list | H2: Verify GET /api/productsList returns all products | I2: API is reachable. | J2: 1. Send GET request to /api/productsList. 2. Inspect response. | K2: Method: GET Endpoint: /api/productsList | L2: Response code is 200 and response contains the products list. | N2: Pass | O2: High | P2: API / Functional | Q2: Yes | R2: P1 | U2: API 1: Get All Products List | V2: https://www.automationexercise.com/api_list
A3: TC-API-002 | B3: AEQA-7 | C3: API Testing | D3: AEQA-34 | E3: Product APIs | F3: AC2 | G3: Unsupported product-list method | H3: Verify POST /api/productsList is rejected | I3: API is reachable. | J3: 1. Send POST request to /api/productsList. 2. Inspect response. | K3: Method: POST Endpoint: /api/productsList | L3: Response code is 405 and message is 'This request method is not supported.'. | N3: Pass | O3: High | P3: API / Functional | Q3: Yes | R3: P2 | U3: API 2: POST To All Products List | V3: https://www.automationexercise.com/api_list
A4: TC-API-003 | B4: AEQA-7 | C4: API Testing | D4: AEQA-35 | E4: Brand APIs | F4: AC1 | G4: Retrieve brand list | H4: Verify GET /api/brandsList returns all brands | I4: API is reachable. | J4: 1. Send GET request to /api/brandsList. 2. Inspect response. | K4: Method: GET Endpoint: /api/brandsList | L4: Response code is 200 and response contains the brands list. | N4: Pass | O4: High | P4: API / Functional | Q4: Yes | R4: P1 | U4: API 3: Get All Brands List | V4: https://www.automationexercise.com/api_list
A5: TC-API-004 | B5: AEQA-7 | C5: API Testing | D5: AEQA-35 | E5: Brand APIs | F5: AC2 | G5: Unsupported brands method | H5: Verify PUT /api/brandsList is rejected | I5: API is reachable. | J5: 1. Send PUT request to /api/brandsList. 2. Inspect response. | K5: Method: PUT Endpoint: /api/brandsList | L5: Response code is 405 and message is 'This request method is not supported.'. | N5: Pass | O5: High | P5: API / Functional | Q5: Yes | R5: P2 | U5: API 4: PUT To All Brands List | V5: https://www.automationexercise.com/api_list
A6: TC-API-005 | B6: AEQA-7 | C6: API Testing | D6: AEQA-36 | E6: Product Search API | F6: AC1 | G6: Search products with valid parameter | H6: Verify POST /api/searchProduct returns matching products | I6: API is reachable. | J6: 1. Send POST request to /api/searchProduct with search_product. 2. Inspect response. | K6: Method: POST Endpoint: /api/searchProduct Use TD-SEARCH Keyword 1 as search_product. | L6: Response code is 200 and response contains searched products. | N6: Pass | O6: High | P6: API / Functional | Q6: Yes | R6: P1 | U6: API 5: POST To Search Product | V6: https://www.automationexercise.com/api_list
A7: TC-API-006 | B7: AEQA-7 | C7: API Testing | D7: AEQA-36 | E7: Product Search API | F7: AC2 | G7: Search products without required parameter | H7: Verify POST /api/searchProduct without search_product returns 400 | I7: API is reachable. | J7: 1. Send POST request to /api/searchProduct without search_product. 2. Inspect response. | K7: Method: POST Endpoint: /api/searchProduct No search_product parameter | L7: Response code is 400 and message states search_product parameter is missing. | N7: Pass | O7: High | P7: API / Functional | Q7: Yes | R7: P2 | U7: API 6: POST To Search Product without search_product parameter | V7: https://www.automationexercise.com/api_list
A8: TC-API-007 | B8: AEQA-7 | C8: API Testing | D8: AEQA-37 | E8: Login Verification API | F8: AC1 | G8: Verify valid credentials | H8: Verify login API returns User exists for valid credentials | I8: A registered API test user exists. | J8: 1. Send POST request to /api/verifyLogin with valid email/password. 2. Inspect response. | K8: Method: POST Endpoint: /api/verifyLogin Use TD-EXISTING credentials. | L8: Response code is 200 and message is 'User exists!'. | N8: Pass | O8: High | P8: API / Functional | Q8: Yes | R8: P1 | U8: API 7: POST To Verify Login with valid details | V8: https://www.automationexercise.com/api_list
A9: TC-API-008 | B9: AEQA-7 | C9: API Testing | D9: AEQA-37 | E9: Login Verification API | F9: AC3 | G9: Missing required credentials | H9: Verify login API returns 400 when email is missing | I9: API is reachable. | J9: 1. Send POST request to /api/verifyLogin with password only. 2. Inspect response. | K9: Method: POST Endpoint: /api/verifyLogin Email: omitted Use TD-EXISTING Password. | L9: Response code is 400 and message states email or password parameter is missing. | N9: Pass | O9: High | P9: API / Functional | Q9: Yes | R9: P2 | U9: API 8: POST To Verify Login without email parameter | V9: https://www.automationexercise.com/api_list
A10: TC-API-009 | B10: AEQA-7 | C10: API Testing | D10: AEQA-37 | E10: Login Verification API | F10: AC4 | G10: Unsupported HTTP method | H10: Verify DELETE /api/verifyLogin is rejected | I10: API is reachable. | J10: 1. Send DELETE request to /api/verifyLogin. 2. Inspect response. | K10: Method: DELETE Endpoint: /api/verifyLogin | L10: Response code is 405 and message is 'This request method is not supported.'. | N10: Pass | O10: High | P10: API / Functional | Q10: Yes | R10: P2 | U10: API 9: DELETE To Verify Login | V10: https://www.automationexercise.com/api_list
A11: TC-API-010 | B11: AEQA-7 | C11: API Testing | D11: AEQA-37 | E11: Login Verification API | F11: AC2 | G11: Verify invalid credentials | H11: Verify login API returns user-not-found for invalid credentials | I11: API is reachable. | J11: 1. Send POST request to /api/verifyLogin with invalid email/password. 2. Inspect response. | K11: Method: POST Endpoint: /api/verifyLogin Use TD-NEGATIVE Unregistered Email + TD-NEGATIVE Wrong Password. | L11: Response code is 404 and message is 'User not found!'. | N11: Pass | O11: High | P11: API / Functional | Q11: Yes | R11: P2 | U11: API 10: POST To Verify Login with invalid details | V11: https://www.automationexercise.com/api_list
A12: TC-API-011 | B12: AEQA-7 | C12: API Testing | D12: AEQA-38 | E12: User Account APIs | F12: AC1 | G12: Create account | H12: Verify POST /api/createAccount creates a new user | I12: Email has not been registered before. | J12: 1. Send POST request to /api/createAccount with all required account fields. 2. Inspect response. | K12: Method: POST Endpoint: /api/createAccount Use TD-API with a fresh email + TD-REGISTER profile/address values. | L12: Response code is 201 and message is 'User created!'. | N12: Pass | O12: High | P12: API / Functional | Q12: Yes | R12: P1 | U12: API 11: POST To Create/Register User Account | V12: https://www.automationexercise.com/api_list
A13: TC-API-012 | B13: AEQA-7 | C13: API Testing | D13: AEQA-38 | E13: User Account APIs | F13: AC2 | G13: Retrieve account | H13: Verify GET /api/getUserDetailByEmail returns user detail | I13: API test account exists. | J13: 1. Send GET request to /api/getUserDetailByEmail with registered email. 2. Inspect response. | K13: Method: GET Endpoint: /api/getUserDetailByEmail Use the email created by TC-API-011. | L13: Response code is 200 and response contains the expected user detail. | N13: Pass | O13: High | P13: API / Functional | Q13: Yes | R13: P1 | U13: API 14: GET user account detail by email | V13: https://www.automationexercise.com/api_list
... A15: TC-API-014 | B15: AEQA-7 | C15: API Testing | D15: AEQA-38 | E15: User Account APIs | F15: AC4 | G15: Delete account | H15: Verify DELETE /api/deleteAccount deletes an existing user | I15: API test account exists. | J15: 1. Send DELETE request to /api/deleteAccount with email/password. 2. Inspect response. | K15: Method: DELETE Endpoint: /api/deleteAccount Use credentials from TC-API-011. | L15: Response code is 200 and message is 'Account deleted!'. | N15: Pass | O15: High | P15: API / Functional | Q15: Yes | R15: P1 | U15: API 12: DELETE METHOD To Delete User Account | V15: https://www.automationexercise.com/api_list

Sheet 98_Jira_Review
A1: Key | B1: Issue Type | C1: Summary | D1: Review Status | E1: Notes
A2: AEQA-1 | B2: Epic | C2: Authentication & Account Management | D2: OK
A3: AEQA-2 | B3: Epic | C3: Product Catalog & Discovery | D3: OK
A4: AEQA-3 | B4: Epic | C4: Shopping Cart Management | D4: OK
A5: AEQA-4 | B5: Epic | C5: Checkout & Order Management | D5: OK
A6: AEQA-5 | B6: Epic | C6: Customer Engagement & Support | D6: OK
A7: AEQA-6 | B7: Epic | C7: Navigation & UI Behavior | D7: OK
A8: AEQA-7 | B8: Epic | C8: API Testing | D8: OK
A9: AEQA-8 | B9: Story | C9: User Registration | D9: OK
A10: AEQA-9 | B10: Story | C10: User Login | D10: OK
A11: AEQA-10 | B11: Story | C11: User Logout | D11: OK
A12: AEQA-11 | B12: Story | C12: Account Deletion | D12: OK
A13: AEQA-12 | B13: Story | C13: View Product Catalog | D13: OK
... A38: AEQA-38 | B38: Story | C38: User Account APIs | D38: OK

Sheet 99_Test_Data
A1: Reusable Test Data - Final Version
A2: Use these values for manual testing. For a new account, change only the numeric suffix when an email is already used.
A3: Data Set | B3: Field | C3: Value | D3: Simple Note
A4: TD-REGISTER | B4: Name | C4: Automation Tester | D4: Use for UI registration.
A5: TD-REGISTER | B5: Email | C5: qa.aeqa.test001@example.com | D5: Next new account: test002, test003, etc.
A6: TD-REGISTER | B6: Password | C6: Test@123 | D6: Reusable UI test password.
A7: TD-REGISTER | B7: Title | C7: Mr | D7: Select a valid title.
A8: TD-REGISTER | B8: Birth Date | C8: 1
A9: TD-REGISTER | B9: Birth Month | C9: January
A10: TD-REGISTER | B10: Birth Year | C10: 2000
A11: TD-REGISTER | B11: First Name | C11: Automation
A12: TD-REGISTER | B12: Last Name | C12: Tester
A13: TD-REGISTER | B13: Company | C13: QA Portfolio
A14: TD-REGISTER | B14: Address | C14: 123 Test Street | D14: Fake test address.
A15: TD-REGISTER | B15: Address2 | C15: Suite 1 | D15: Optional UI field; useful for API profile data.
A16: TD-REGISTER | B16: Country | C16: Canada | D16: Choose Canada in the dropdown.
A17: TD-REGISTER | B17: State | C17: Test State
A18: TD-REGISTER | B18: City | C18: Test City
A19: TD-REGISTER | B19: Zipcode | C19: 700000
A20: TD-REGISTER | B20: Mobile | C20: 0900000000 | D20: Fake test phone number.
A21: TD-EXISTING | B21: Email | C21: qa.aeqa.test001@example.com | D21: After registration succeeds, keep the actual registered email here.
A22: TD-EXISTING | B22: Password | C22: Test@123 | D22: Password of the existing UI account.
A23: TD-PAYMENT | B23: Name on Card | C23: Automation Tester | D23: Test data only.
A24: TD-PAYMENT | B24: Card Number | C24: 4111111111111111 | D24: Test data only; stored as text.
A25: TD-PAYMENT | B25: CVC | C25: 123 | D25: Test data only.
A26: TD-PAYMENT | B26: Expiration Month | C26: 12
A27: TD-PAYMENT | B27: Expiration Year | C27: 2030
A28: TD-ORDER | B28: Comment | C28: Portfolio checkout test | D28: Use for checkout comment.
A29: TD-CONTACT | B29: Name | C29: Automation Tester | D29: Use for Contact Us.
A30: TD-CONTACT | B30: Email | C30: qa.contact@example.com
A31: TD-CONTACT | B31: Subject | C31: QA Portfolio Test
A32: TD-CONTACT | B32: Message | C32: Manual test execution for QA portfolio.
A33: TD-SEARCH | B33: Keyword 1 | C33: top | D33: Official API example and UI search keyword.
A34: TD-SEARCH | B34: Keyword 2 | C34: jean | D34: Official API example and UI search keyword.
A35: TD-REVIEW | B35: Name | C35: Automation Tester | D35: Use for product review.
A36: TD-REVIEW | B36: Email | C36: qa.review@example.com
A37: TD-REVIEW | B37: Review | C37: Great practice product.
A38: TD-SUBSCRIPTION | B38: Home Email | C38: qa.subscription@example.com | D38: Use for Home page subscription.
A39: TD-SUBSCRIPTION | B39: Cart Email | C39: qa.subscription2@example.com | D39: Use for Cart page subscription.
A40: TD-NEGATIVE | B40: Invalid Email Format | C40: testemail | D40: Use for format validation.
...
